<robot
  name="ucrbot">
  <link
    name="base_link">
    <inertial>
      <origin
        xyz="-0.0174154107068305 0.0658230329314833 0.41"
        rpy="0 0 0" />
      <mass
        value="7.17075879708735" />
      <inertia
        ixx="0.0712694538653391"
        ixy="0.000136337717153692"
        ixz="-0.000161646044879388"
        iyy="0.0592974234763051"
        iyz="0.0150242886962805"
        izz="0.036203225755511" />
    </inertial>
    <visual>
      <origin
        xyz="0 0 0"
        rpy="0 0 0" />
      <geometry>
        <mesh
          filename="package://ucrbot/meshes/base_link.STL" />
      </geometry>
      <material
        name="">
        <color
          rgba="0.752941176470588 0.752941176470588 0.752941176470588 1" />
      </material>
    </visual>
    <collision>
      <origin
        xyz="0 0 0"
        rpy="0 0 0" />
      <geometry>
        <mesh
          filename="package://ucrbot/meshes/base_link.STL" />
      </geometry>
    </collision>
  </link>
  <link
    name="front_holder">
    <inertial>
      <origin
        xyz="0.00255605985229366 -0.0170761250332246 -0.0021770708658958"
        rpy="0 0 0" />
      <mass
        value="2.95565551037739" />
      <inertia
        ixx="0.00979367949400859"
        ixy="-6.1351638526207E-06"
        ixz="0.000730679286902558"
        iyy="0.0249517390279264"
        iyz="-0.000287272828549466"
        izz="0.0314014275502981" />
    </inertial>
    <visual>
      <origin
        xyz="0 0 0"
        rpy="0 0 0" />
      <geometry>
        <mesh
          filename="package://ucrbot/meshes/front_holder.STL" />
      </geometry>
      <material
        name="">
        <color
          rgba="0.752941176470588 0.752941176470588 0.752941176470588 1" />
      </material>
    </visual>
    <collision>
      <origin
        xyz="0 0 0"
        rpy="0 0 0" />
      <geometry>
        <mesh
          filename="package://ucrbot/meshes/front_holder.STL" />
      </geometry>
    </collision>
  </link>
  <joint
    name="steer_joint"
    type="revolute">
    <origin
      xyz="-0.017385 -0.2605 0"
      rpy="1.5708 1.257E-19 0.0020529" />
    <parent
      link="base_link" />
    <child
      link="front_holder" />
    <axis
      xyz="0 1 0" />
    <limit
      lower="-0.5"
      upper="0.5"
      effort="0"
      velocity="1" />
  </joint>
  <link
    name="front_left_wheel">
    <inertial>
      <origin
        xyz="0.0175614847435544 -3.75532938079459E-14 5.55111512312578E-17"
        rpy="0 0 0" />
      <mass
        value="2.96434014657607" />
      <inertia
        ixx="0.0114002485862291"
        ixy="-1.14968400817537E-14"
        ixz="8.58044375568606E-18"
        iyy="0.00602162995230769"
        iyz="9.89488338535986E-19"
        izz="0.00602162995230769" />
    </inertial>
    <visual>
      <origin
        xyz="0 0 0"
        rpy="0 0 0" />
      <geometry>
        <mesh
          filename="package://ucrbot/meshes/front_left_wheel.STL" />
      </geometry>
      <material
        name="">
        <color
          rgba="0.752941176470588 0.752941176470588 0.752941176470588 1" />
      </material>
    </visual>
    <collision>
      <origin
        xyz="0 0 0"
        rpy="0 0 0" />
      <geometry>
        <mesh
          filename="package://ucrbot/meshes/front_left_wheel.STL" />
      </geometry>
    </collision>
  </link>
  <joint
    name="front_left_drive_joint"
    type="continuous">
    <origin
      xyz="-0.0325001601438198 -0.0614618553961881 0"
      rpy="3.14159265358979 4.33680868994202E-19 3.14159265358979" />
    <parent
      link="front_holder" />
    <child
      link="front_left_wheel" />
    <axis
      xyz="-1 0 0" />
  </joint>
  <link
    name="front_right_wheel">
    <inertial>
      <origin
        xyz="0.0175614847440073 3.75394160201381E-14 1.66533453693773E-16"
        rpy="0 0 0" />
      <mass
        value="2.96434014657607" />
      <inertia
        ixx="0.011400248586229"
        ixy="1.1496668554298E-14"
        ixz="8.93026836290209E-18"
        iyy="0.00602162995230769"
        iyz="6.44411201662903E-19"
        izz="0.00602162995230769" />
    </inertial>
    <visual>
      <origin
        xyz="0 0 0"
        rpy="0 0 0" />
      <geometry>
        <mesh
          filename="package://ucrbot/meshes/front_right_wheel.STL" />
      </geometry>
      <material
        name="">
        <color
          rgba="0.752941176470588 0.752941176470588 0.752941176470588 1" />
      </material>
    </visual>
    <collision>
      <origin
        xyz="0 0 0"
        rpy="0 0 0" />
      <geometry>
        <mesh
          filename="package://ucrbot/meshes/front_right_wheel.STL" />
      </geometry>
    </collision>
  </link>
  <joint
    name="front_right_drive_joint"
    type="continuous">
    <origin
      xyz="0.0325001601436291 -0.0614618553960491 0"
      rpy="0 0 0" />
    <parent
      link="front_holder" />
    <child
      link="front_right_wheel" />
    <axis
      xyz="1 0 0" />
  </joint>
  <link
    name="rear_holder">
    <inertial>
      <origin
        xyz="0.00332218345670297 -0.0978727791645708 0.000686032593414897"
        rpy="0 0 0" />
      <mass
        value="2.62485787651341" />
      <inertia
        ixx="0.00754609839474726"
        ixy="0.00061660222899901"
        ixz="-8.40567181180612E-05"
        iyy="0.0222619885517914"
        iyz="-3.89782227790271E-05"
        izz="0.0273906877517284" />
    </inertial>
    <visual>
      <origin
        xyz="0 0 0"
        rpy="0 0 0" />
      <geometry>
        <mesh
          filename="package://ucrbot/meshes/rear_holder.STL" />
      </geometry>
      <material
        name="">
        <color
          rgba="0.752941176470588 0.752941176470588 0.752941176470588 1" />
      </material>
    </visual>
    <collision>
      <origin
        xyz="0 0 0"
        rpy="0 0 0" />
      <geometry>
        <mesh
          filename="package://ucrbot/meshes/rear_holder.STL" />
      </geometry>
    </collision>
  </link>
  <joint
    name="rear_rolling_joint"
    type="continuous">
    <origin
      xyz="-0.0173847686329671 -0.494499991301886 -0.0614618553961184"
      rpy="0 0 0" />
    <parent
      link="base_link" />
    <child
      link="rear_holder" />
    <axis
      xyz="0 -1 0" />
  </joint>
  <link
    name="rear_left_wheel">
    <inertial>
      <origin
        xyz="0.0175616562104351 9.38575994702262E-10 6.93889390390723E-17"
        rpy="0 0 0" />
      <mass
        value="2.96434014657606" />
      <inertia
        ixx="0.011400248586229"
        ixy="2.87458252733412E-10"
        ixz="2.93116891355632E-18"
        iyy="0.00602162995230769"
        iyz="8.12166916911443E-19"
        izz="0.00602162995230767" />
    </inertial>
    <visual>
      <origin
        xyz="0 0 0"
        rpy="0 0 0" />
      <geometry>
        <mesh
          filename="package://ucrbot/meshes/rear_left_wheel.STL" />
      </geometry>
      <material
        name="">
        <color
          rgba="0.752941176470588 0.752941176470588 0.752941176470588 1" />
      </material>
    </visual>
    <collision>
      <origin
        xyz="0 0 0"
        rpy="0 0 0" />
      <geometry>
        <mesh
          filename="package://ucrbot/meshes/rear_left_wheel.STL" />
      </geometry>
    </collision>
  </link>
  <joint
    name="rear_left_drive_joint"
    type="continuous">
    <origin
      xyz="-0.032499981729268 -0.130000017743615 0"
      rpy="0 0 -3.14159265358979" />
    <parent
      link="rear_holder" />
    <child
      link="rear_left_wheel" />
    <axis
      xyz="-1 0 0" />
  </joint>
  <link
    name="rear_right_wheel">
    <inertial>
      <origin
        xyz="0.017561656210435 0 0"
        rpy="0 0 0" />
      <mass
        value="2.96434014657607" />
      <inertia
        ixx="0.011400248586229"
        ixy="2.87458251783402E-10"
        ixz="-2.87458249351805E-10"
        iyy="0.00602162995230771"
        iyz="-1.50888407884945E-17"
        izz="0.00602162995230771" />
    </inertial>
    <visual>
      <origin
        xyz="0 0 0"
        rpy="0 0 0" />
      <geometry>
        <mesh
          filename="package://ucrbot/meshes/rear_right_wheel.STL" />
      </geometry>
      <material
        name="">
        <color
          rgba="0.752941176470588 0.752941176470588 0.752941176470588 1" />
      </material>
    </visual>
    <collision>
      <origin
        xyz="0 0 0"
        rpy="0 0 0" />
      <geometry>
        <mesh
          filename="package://ucrbot/meshes/rear_right_wheel.STL" />
      </geometry>
    </collision>
  </link>
  <joint
    name="rear_right_drive_joint"
    type="continuous">
    <origin
      xyz="0.032499995624872 -0.130000014269716 0"
      rpy="1.57079632679489 0 0" />
    <parent
      link="rear_holder" />
    <child
      link="rear_right_wheel" />
    <axis
      xyz="0.999999999999997 0 0" />
  </joint>
  
  <link name="base_footprint">
    <visual>
      <origin xyz="0 0 0" rpy="0 0 0" />
      <geometry>
          <box size="0.001 0.001 0.001" />
      </geometry>
    </visual>
  </link>
  <joint name="base_footprint_joint" type="fixed">
    <origin xyz="-0.64 0 -0.04" rpy="0 0 1.5708" />        
    <parent link="base_footprint"/>
    <child link="base_link" />
  </joint>
</robot>
