<robot
  name="ucrbot">
  <link
    name="base_link">
    <inertial>
      <origin
        xyz="-4.3794772349764E-05 0.00950986062864663 0.0178261006997258"
        rpy="0 0 0" />
      <mass
        value="5.84279395822244" />
      <inertia
        ixx="0.0683791349055411"
        ixy="0.000164704471624976"
        ixz="0.000141663263014248"
        iyy="0.0347965228767514"
        iyz="-0.0139342747763736"
        izz="0.0554084177086021" />
    </inertial>
    <visual>
      <origin
        xyz="0 0 0"
        rpy="0 0 0" />
      <geometry>
        <mesh
          filename="package://ucrbot/meshes/base_link.STL" />
      </geometry>
      <material
        name="">
        <color
          rgba="0.752941176470588 0.752941176470588 0.752941176470588 1" />
      </material>
    </visual>
    <collision>
      <origin
        xyz="0 0 0"
        rpy="0 0 0" />
      <geometry>
        <mesh
          filename="package://ucrbot/meshes/base_link.STL" />
      </geometry>
    </collision>
  </link>
  <link
    name="front_holder">
    <inertial>
      <origin
        xyz="0.014806175607645 -0.0570751937941159 -0.00267590102482992"
        rpy="0 0 0" />
      <mass
        value="2.40596398964761" />
      <inertia
        ixx="0.00778278418687859"
        ixy="0.00160051056207382"
        ixz="0.00065149814674459"
        iyy="0.0211018036191222"
        iyz="-0.000352721924642226"
        izz="0.0262248138805438" />
    </inertial>
    <visual>
      <origin
        xyz="0 0 0"
        rpy="0 0 0" />
      <geometry>
        <mesh
          filename="package://ucrbot/meshes/front_holder.STL" />
      </geometry>
      <material
        name="">
        <color
          rgba="0.752941176470588 0.752941176470588 0.752941176470588 1" />
      </material>
    </visual>
    <collision>
      <origin
        xyz="0 0 0"
        rpy="0 0 0" />
      <geometry>
        <mesh
          filename="package://ucrbot/meshes/front_holder.STL" />
      </geometry>
    </collision>
  </link>
  <joint
    name="front_steer_joint"
    type="revolute">
    <origin
      xyz="0 0.145 0"
      rpy="1.5708 -2.5737E-19 -0.0042033" />
    <parent
      link="base_link" />
    <child
      link="front_holder" />
    <axis
      xyz="0 1 0" />
    <limit
      lower="-0.5"
      upper="0.5"
      effort="0"
      velocity="1" />
  </joint>
  <link
    name="front_left_wheel">
    <inertial>
      <origin
        xyz="-0.0514249072103103 -7.99907419551937E-07 -1.38548264350113E-06"
        rpy="0 0 0" />
      <mass
        value="3.40151426652415" />
      <inertia
        ixx="0.0119983871481024"
        ixy="-1.03010576832154E-07"
        ixz="-1.78419851125031E-07"
        iyy="0.00744120697182477"
        iyz="1.71002919149062E-08"
        izz="0.0074412267176927" />
    </inertial>
    <visual>
      <origin
        xyz="0 0 0"
        rpy="0 0 0" />
      <geometry>
        <mesh
          filename="package://ucrbot/meshes/front_left_wheel.STL" />
      </geometry>
      <material
        name="">
        <color
          rgba="0.752941176470588 0.752941176470588 0.752941176470588 1" />
      </material>
    </visual>
    <collision>
      <origin
        xyz="0 0 0"
        rpy="0 0 0" />
      <geometry>
        <mesh
          filename="package://ucrbot/meshes/front_left_wheel.STL" />
      </geometry>
    </collision>
  </link>
  <joint
    name="front_left_drive_joint"
    type="continuous">
    <origin
      xyz="0 -0.111599999999999 0"
      rpy="-0.825519933902369 5.29090660172926E-16 4.88758339356465E-16" />
    <parent
      link="front_holder" />
    <child
      link="front_left_wheel" />
    <axis
      xyz="-1 0 0" />
  </joint>
  <link
    name="front_right_wheel">
    <inertial>
      <origin
        xyz="0.0187970781771947 0 5.55111512312578E-17"
        rpy="0 0 0" />
      <mass
        value="2.99473805676772" />
      <inertia
        ixx="0.0114557818911859"
        ixy="-7.88587673893754E-19"
        ixz="-2.05659599593344E-18"
        iyy="0.00605699121158563"
        iyz="2.16840434497101E-19"
        izz="0.00605699121158563" />
    </inertial>
    <visual>
      <origin
        xyz="0 0 0"
        rpy="0 0 0" />
      <geometry>
        <mesh
          filename="package://ucrbot/meshes/front_right_wheel.STL" />
      </geometry>
      <material
        name="">
        <color
          rgba="0.752941176470588 0.752941176470588 0.752941176470588 1" />
      </material>
    </visual>
    <collision>
      <origin
        xyz="0 0 0"
        rpy="0 0 0" />
      <geometry>
        <mesh
          filename="package://ucrbot/meshes/front_right_wheel.STL" />
      </geometry>
    </collision>
  </link>
  <joint
    name="front_right_drive_joint"
    type="continuous">
    <origin
      xyz="0.0304259917277344 -0.1116 0"
      rpy="0.482824124437366 4.77048955893622E-17 -9.41087485717418E-17" />
    <parent
      link="front_holder" />
    <child
      link="front_right_wheel" />
    <axis
      xyz="-1 0 0" />
  </joint>
  <link
    name="rear_holder">
    <inertial>
      <origin
        xyz="0.0176075032786513 0.000863965630468672 0.0917481173360872"
        rpy="0 0 0" />
      <mass
        value="2.0893671403394" />
      <inertia
        ixx="0.00627254638864915"
        ixy="-5.78652155245838E-05"
        ixz="-0.00185375986143832"
        iyy="0.0228378600704497"
        iyz="2.2346724233569E-05"
        izz="0.0183164526777356" />
    </inertial>
    <visual>
      <origin
        xyz="0 0 0"
        rpy="0 0 0" />
      <geometry>
        <mesh
          filename="package://ucrbot/meshes/rear_holder.STL" />
      </geometry>
      <material
        name="">
        <color
          rgba="0.752941176470588 0.752941176470588 0.752941176470588 1" />
      </material>
    </visual>
    <collision>
      <origin
        xyz="0 0 0"
        rpy="0 0 0" />
      <geometry>
        <mesh
          filename="package://ucrbot/meshes/rear_holder.STL" />
      </geometry>
    </collision>
  </link>
  <joint
    name="rear_holder_joint"
    type="continuous">
    <origin
      xyz="0 -0.0899999999999911 -0.1116"
      rpy="1.5707963267949 -0.00257589519748985 1.57723230125107E-19" />
    <parent
      link="base_link" />
    <child
      link="rear_holder" />
    <axis
      xyz="0 0 1" />
  </joint>
  <link
    name="rear_wheel">
    <inertial>
      <origin
        xyz="-0.00430132418549638 2.2019730927525E-07 8.21789993915578E-07"
        rpy="0 0 0" />
      <mass
        value="6.39625232328686" />
      <inertia
        ixx="0.0234541690433644"
        ixy="1.19692743157598E-07"
        ixz="4.46700721104321E-07"
        iyy="0.0296312102042264"
        iyz="9.87180102333257E-09"
        izz="0.0296312444014119" />
    </inertial>
    <visual>
      <origin
        xyz="0 0 0"
        rpy="0 0 0" />
      <geometry>
        <mesh
          filename="package://ucrbot/meshes/rear_wheel.STL" />
      </geometry>
      <material
        name="">
        <color
          rgba="0.752941176470588 0.752941176470588 0.752941176470588 1" />
      </material>
    </visual>
    <collision>
      <origin
        xyz="0 0 0"
        rpy="0 0 0" />
      <geometry>
        <mesh
          filename="package://ucrbot/meshes/rear_wheel.STL" />
      </geometry>
    </collision>
  </link>
  <joint
    name="rear_drive_joint"
    type="continuous">
    <origin
      xyz="0 0 0.133000000000013"
      rpy="2.34234748597585 -1.80411241501588E-16 1.15055534544162E-15" />
    <parent
      link="rear_holder" />
    <child
      link="rear_wheel" />
    <axis
      xyz="-1 0 0" />
  </joint>
  
  <link name="odom_link" />
  <joint name="odom_joint" type="fixed">
    <origin xyz="0.223 -0.001 0.1116" rpy="0 0 -1.5708" />        
    <parent link="odom_link"/>
    <child link="base_link" />
  </joint>
  
  <link name="base_footprint" />
  <joint name="base_footprint_joint" type="fixed">
    <origin xyz="-0.1575 0 0" rpy="0 0 0" />
    <parent link="base_footprint" />
    <child link="odom_link" />
  </joint>
  
  <link name="imu" >
  </link>
  <joint name="imu_joint" type="fixed" >
    <!-- for the odom direction of steer_drive_control -->
    <origin xyz="-0.024 0.15475 0.1039" rpy="0 0 0" />
    <parent link="base_link" />
    <child link="imu" />
  </joint>
  
  <link name="camera" >
  </link>
  <joint name="camera_joint" type="fixed" >
    <origin xyz="0 0 0.1286" rpy="0 0 0" />
    <parent link="base_link" />
    <child link="camera" />
  </joint>
  
  <gazebo reference="imu">
    <gravity>true</gravity>
    <sensor name="imu_sensor" type="imu">
      <always_on>true</always_on>
      <update_rate>100</update_rate>
      <visualize>true</visualize>
      <topic>imu_data</topic>
      <plugin filename="libgazebo_ros_imu_sensor.so" name="imu_plugin">
        <topicName>imu_data</topicName>
        <bodyName>imu</bodyName>
        <updateRateHZ>10.0</updateRateHZ>
        <gaussianNoise>0.0</gaussianNoise>
        <xyzOffset>0 0 0</xyzOffset>
        <rpyOffset>0 0 0</rpyOffset>
        <frameName>imu</frameName>
      </plugin>
      <pose>0 0 0 0 0 0</pose>
    </sensor>
  </gazebo>
</robot>
