<robot
  name="ucrbot">
  <link
    name="base_link">
    <inertial>
      <origin
        xyz="-4.3795E-05 0.0095099 0.017826"
        rpy="0 0 0" />
      <mass
        value="5.8428" />
      <inertia
        ixx="0.068379"
        ixy="0.0001647"
        ixz="0.00014166"
        iyy="0.034797"
        iyz="-0.013934"
        izz="0.055408" />
    </inertial>
    <visual>
      <origin
        xyz="0 0 0"
        rpy="0 0 0" />
      <geometry>
        <mesh
          filename="package://ucrbot/meshes/base_link.STL" />
      </geometry>
      <material
        name="">
        <color
          rgba="0.75294 0.75294 0.75294 1" />
      </material>
    </visual>
    <collision>
      <origin
        xyz="0 0 0"
        rpy="0 0 0" />
      <geometry>
        <mesh
          filename="package://ucrbot/meshes/base_link.STL" />
      </geometry>
    </collision>
  </link>
  <link
    name="front_holder">
    <inertial>
      <origin
        xyz="0.014806 -0.057075 -0.0026759"
        rpy="0 0 0" />
      <mass
        value="2.406" />
      <inertia
        ixx="0.0077828"
        ixy="0.0016005"
        ixz="0.0006515"
        iyy="0.021102"
        iyz="-0.00035272"
        izz="0.026225" />
    </inertial>
    <visual>
      <origin
        xyz="0 0 0"
        rpy="0 0 0" />
      <geometry>
        <mesh
          filename="package://ucrbot/meshes/front_holder.STL" />
      </geometry>
      <material
        name="">
        <color
          rgba="0.75294 0.75294 0.75294 1" />
      </material>
    </visual>
    <collision>
      <origin
        xyz="0 0 0"
        rpy="0 0 0" />
      <geometry>
        <mesh
          filename="package://ucrbot/meshes/front_holder.STL" />
      </geometry>
    </collision>
  </link>
  <joint
    name="front_steer_joint"
    type="revolute">
    <origin
      xyz="0 0.145 0"
      rpy="1.5708 -2.5737E-19 -0.0042033" />
    <parent
      link="base_link" />
    <child
      link="front_holder" />
    <axis
      xyz="0 1 0" />
    <limit
      lower="-0.5"
      upper="0.5"
      effort="0"
      velocity="0" />
  </joint>
  <link
    name="front_left_wheel">
    <inertial>
      <origin
        xyz="-0.051425 -0.041776 -0.045271"
        rpy="0 0 0" />
      <mass
        value="3.4015" />
      <inertia
        ixx="0.011998"
        ixy="-1.0301E-07"
        ixz="-1.7842E-07"
        iyy="0.0074412"
        iyz="1.71E-08"
        izz="0.0074412" />
    </inertial>
    <visual>
      <origin
        xyz="0 0 0"
        rpy="0 0 0" />
      <geometry>
        <mesh
          filename="package://ucrbot/meshes/front_left_wheel.STL" />
      </geometry>
      <material
        name="">
        <color
          rgba="0.75294 0.75294 0.75294 1" />
      </material>
    </visual>
    <collision>
      <origin
        xyz="0 0 0"
        rpy="0 0 0" />
      <geometry>
        <mesh
          filename="package://ucrbot/meshes/front_left_wheel.STL" />
      </geometry>
    </collision>
  </link>
  <joint
    name="front_left_drive_joint"
    type="continuous">
    <origin
      xyz="0 -0.05 0"
      rpy="-0.82552 5.3169E-16 4.9093E-16" />
    <parent
      link="front_holder" />
    <child
      link="front_left_wheel" />
    <axis
      xyz="1 0 0" />
  </joint>
  <link
    name="front_right_wheel">
    <inertial>
      <origin
        xyz="0.018797 -2.7756E-17 -5.5511E-17"
        rpy="0 0 0" />
      <mass
        value="2.9947" />
      <inertia
        ixx="0.011456"
        ixy="-9.2411E-19"
        ixz="-2.1735E-18"
        iyy="0.006057"
        iyz="4.3368E-19"
        izz="0.006057" />
    </inertial>
    <visual>
      <origin
        xyz="0 0 0"
        rpy="0 0 0" />
      <geometry>
        <mesh
          filename="package://ucrbot/meshes/front_right_wheel.STL" />
      </geometry>
      <material
        name="">
        <color
          rgba="0.75294 0.75294 0.75294 1" />
      </material>
    </visual>
    <collision>
      <origin
        xyz="0 0 0"
        rpy="0 0 0" />
      <geometry>
        <mesh
          filename="package://ucrbot/meshes/front_right_wheel.STL" />
      </geometry>
    </collision>
  </link>
  <joint
    name="front_right_drive_joint"
    type="continuous">
    <origin
      xyz="0.030426 -0.1116 0"
      rpy="0.48282 4.3368E-17 -8.3917E-17" />
    <parent
      link="front_holder" />
    <child
      link="front_right_wheel" />
    <axis
      xyz="1 0 0" />
  </joint>
  <link
    name="rear_holder">
    <inertial>
      <origin
        xyz="0.017608 0.00086397 0.091748"
        rpy="0 0 0" />
      <mass
        value="2.0894" />
      <inertia
        ixx="0.0062725"
        ixy="-5.7865E-05"
        ixz="-0.0018538"
        iyy="0.022838"
        iyz="2.2347E-05"
        izz="0.018316" />
    </inertial>
    <visual>
      <origin
        xyz="0 0 0"
        rpy="0 0 0" />
      <geometry>
        <mesh
          filename="package://ucrbot/meshes/rear_holder.STL" />
      </geometry>
      <material
        name="">
        <color
          rgba="0.75294 0.75294 0.75294 1" />
      </material>
    </visual>
    <collision>
      <origin
        xyz="0 0 0"
        rpy="0 0 0" />
      <geometry>
        <mesh
          filename="package://ucrbot/meshes/rear_holder.STL" />
      </geometry>
    </collision>
  </link>
  <joint
    name="rear_holder_joint"
    type="continuous">
    <origin
      xyz="0 -0.09 -0.1116"
      rpy="1.5708 -0.0025759 1.5772E-19" />
    <parent
      link="base_link" />
    <child
      link="rear_holder" />
    <axis
      xyz="0 0 1" />
  </joint>
  <link
    name="rear_wheel">
    <inertial>
      <origin
        xyz="-0.0043013 -0.0099998 8.2179E-07"
        rpy="0 0 0" />
      <mass
        value="6.3963" />
      <inertia
        ixx="0.023454"
        ixy="1.1969E-07"
        ixz="4.467E-07"
        iyy="0.029631"
        iyz="9.8718E-09"
        izz="0.029631" />
    </inertial>
    <visual>
      <origin
        xyz="0 0 0"
        rpy="0 0 0" />
      <geometry>
        <mesh
          filename="package://ucrbot/meshes/rear_wheel.STL" />
      </geometry>
      <material
        name="">
        <color
          rgba="0.75294 0.75294 0.75294 1" />
      </material>
    </visual>
    <collision>
      <origin
        xyz="0 0 0"
        rpy="0 0 0" />
      <geometry>
        <mesh
          filename="package://ucrbot/meshes/rear_wheel.STL" />
      </geometry>
    </collision>
  </link>
  <joint
    name="rear_drive_joint"
    type="continuous">
    <origin
      xyz="0 -0.0069725 0.14017"
      rpy="2.3423 -1.8041E-16 1.1506E-15" />
    <parent
      link="rear_holder" />
    <child
      link="rear_wheel" />
    <axis
      xyz="1 0 0" />
  </joint>
  
  <link name="base_footprint">
    <visual>
      <origin xyz="0 0 0" rpy="0 0 0" />
      <geometry>
          <box size="0.001 0.001 0.001" />
      </geometry>
    </visual>
  </link>
  <joint name="base_footprint_joint" type="fixed">
    <origin xyz="0 0 0" rpy="0 0 -1.5708" />        
    <parent link="base_footprint"/>
    <child link="base_link" />
  </joint>
</robot>
